Workbook

Sheet data
A1: 아파트코드 | B1: 아파트명 | C1: 위도 | D1: 경도 | E1: 세대수 | F1: 공급승인일자 | G1: 입주세대 합계 | H1: 입주율 | I1: 1개월 | J1: 2개월 | K1: 3개월 | L1: 4개월 | M1: 5개월 | N1: 6개월 | O1: 7개월 | P1: 8개월 | Q1: 9개월 | R1: 10개월 | S1: 11개월 | T1: 12개월 | U1: 13개월 | V1: 14개월 | W1: 15개월 | X1: 16개월 | Y1: 17개월 | Z1: 18개월 | AA1: 19개월 | AB1: 20개월 | AC1: 21개월 | AD1: 22개월 | AE1: 23개월 | AF1: 24개월 | AG1: 25개월 | AH1: 26개월 | AI1: 27개월 | AJ1: 28개월 | AK1: 29개월 | AL1: 30개월 | AM1: 31개월 | AN1: 32개월 | AO1: 33개월 | AP1: 34개월 | AQ1: 35개월 | AR1: 36개월 | AS1: 37개월 | AT1: 38개월 | AU1: 39개월 | AV1: 40개월 | AW1: 41개월 | AX1: 42개월 | AY1: 43개월 | AZ1: 44개월 | BA1: 45개월 | BB1: 46개월 | BC1: 47개월 | BD1: 48개월
A2: 201185 | B2: 방촌역 태왕아너스 | C2: =IFERROR(VLOOKUP($A2,위치!$B:$F,4,FALSE),"") -> 35.881076 | D2: =IFERROR(VLOOKUP($A2,위치!$B:$F,5,FALSE),"") -> 128.66774 | E2: 256 | F2: 44208 | G2: 256 | H2: 1 | K2: 26 | L2: 152 | M2: 55 | N2: 15 | O2: 6 | U2: 1 | AE2: 1
A3: 201226 | B3: 힐스테이트데시앙 도남 2단지(C2BL) | C3: =IFERROR(VLOOKUP($A3,위치!$B:$F,4,FALSE),"") -> 35.950474 | D3: =IFERROR(VLOOKUP($A3,위치!$B:$F,5,FALSE),"") -> 128.57945 | E3: 658 | F3: 44448 | G3: 658 | H3: 1 | J3: 2 | K3: 307 | L3: 237 | M3: 51 | N3: 15 | O3: 23 | P3: 9 | Q3: 6 | R3: 3 | V3: 2 | W3: 1 | Y3: 1 | AB3: 1
A4: 201324 | B4: 설화명곡역 우방아이유쉘 | C4: =IFERROR(VLOOKUP($A4,위치!$B:$F,4,FALSE),"") -> 35.796178 | D4: =IFERROR(VLOOKUP($A4,위치!$B:$F,5,FALSE),"") -> 128.4836 | E4: 320 | F4: 45015 | G4: 314 | H4: 0.9813 | J4: 9 | K4: 159 | L4: 83 | M4: 30 | N4: 18 | O4: 4 | P4: 6 | R4: 1 | U4: 1 | V4: 1 | AC4: 1 | AE4: 1
A5: 201308 | B5: 두류센트레빌더시티아파트 | C5: =IFERROR(VLOOKUP($A5,위치!$B:$F,4,FALSE),"") -> 35.852321 | D5: =IFERROR(VLOOKUP($A5,위치!$B:$F,5,FALSE),"") -> 128.54954 | E5: 333 | F5: 44887 | G5: 333 | H5: 1 | J5: 1 | K5: 98 | L5: 104 | M5: 57 | N5: 31 | O5: 19 | P5: 8 | Q5: 2 | R5: 3 | T5: 3 | U5: 4 | V5: 1 | W5: 1 | X5: 1
A6: 201188 | B6: 중산코오롱하늘채메트로폴리스(하늘채더퍼스트) | C6: =IFERROR(VLOOKUP($A6,위치!$B:$F,4,FALSE),"") -> 35.833619 | D6: =IFERROR(VLOOKUP($A6,위치!$B:$F,5,FALSE),"") -> 128.72554 | E6: 1184 | F6: 44203 | G6: 1183 | H6: 0.9992 | L6: 464 | M6: 382 | N6: 166 | O6: 83 | P6: 31 | Q6: 20 | R6: 12 | S6: 12 | T6: 11 | U6: 2
A7: 201357 | B7: 서대구역 화성파크드림 3단지 | C7: =IFERROR(VLOOKUP($A7,위치!$B:$F,4,FALSE),"") -> 35.870553 | D7: =IFERROR(VLOOKUP($A7,위치!$B:$F,5,FALSE),"") -> 128.54721 | E7: 184 | F7: 45203 | G7: 184 | H7: 1 | I7: 3 | J7: 65 | K7: 18 | L7: 9 | M7: 5 | N7: 1 | O7: 2 | R7: 1 | AI7: 79 | AJ7: 1
A8: 201298 | B8: 서대구KTX3-2블럭 영무예다음 | C8: =IFERROR(VLOOKUP($A8,위치!$B:$F,4,FALSE),"") -> 35.876006 | D8: =IFERROR(VLOOKUP($A8,위치!$B:$F,5,FALSE),"") -> 128.54713 | E8: 283 | F8: 44957 | G8: 282 | H8: 0.9965 | K8: 3 | L8: 123 | M8: 32 | N8: 15 | O8: 10 | P8: 8 | Q8: 4 | R8: 3 | T8: 2 | U8: 1 | V8: 1 | W8: 6 | Y8: 1 | Z8: 1 | AB8: 1 | AF8: 71
A9: 201385 | B9: 대명동 공공지원임대주택2단지(이랜드피어) | C9: =IFERROR(VLOOKUP($A9,위치!$B:$F,4,FALSE),"") -> 35.85629 | D9: =IFERROR(VLOOKUP($A9,위치!$B:$F,5,FALSE),"") -> 128.58642 | E9: 270 | F9: 45176 | G9: 270 | H9: 1 | I9: 1 | J9: 28 | K9: 74 | L9: 41 | M9: 9 | N9: 1 | O9: 1 | Q9: 2 | R9: 5 | S9: 3 | T9: 8 | U9: 9 | V9: 7 | W9: 7 | X9: 10 | Y9: 12 | Z9: 11 | AA9: 3 | AB9: 7 | AC9: 9 | AD9: 8 | AE9: 3 | AF9: 6 | AG9: 4 | AS9: 1
A10: 201372 | B10: 동대구역화성파크드림 | C10: =IFERROR(VLOOKUP($A10,위치!$B:$F,4,FALSE),"") -> 35.883127 | D10: =IFERROR(VLOOKUP($A10,위치!$B:$F,5,FALSE),"") -> 128.62496 | E10: 1304 | F10: 45099 | G10: 1303 | H10: 0.9992 | I10: 35 | J10: 512 | K10: 336 | L10: 148 | M10: 109 | N10: 76 | O10: 45 | P10: 14 | Q10: 8 | R10: 2 | S10: 3 | T10: 5 | U10: 2 | V10: 2 | W10: 4 | AL10: 1 | AQ10: 1
A11: 201317 | B11: 동대구해모로스퀘어웨스트 | C11: =IFERROR(VLOOKUP($A11,위치!$B:$F,4,FALSE),"") -> 35.88937 | D11: =IFERROR(VLOOKUP($A11,위치!$B:$F,5,FALSE),"") -> 128.62619 | E11: 1122 | F11: 44992 | G11: 1122 | H11: 1 | J11: 88 | K11: 464 | L11: 242 | M11: 115 | N11: 43 | O11: 32 | P11: 26 | Q11: 16 | R11: 24 | S11: 4 | T11: 3 | U11: 1 | V11: 1 | X11: 1 | Y11: 9 | Z11: 3 | AB11: 1 | AC11: 47 | AF11: 1 | AH11: 1
A12: 201282 | B12: 서대구 KTX 3-1블럭 영무예다음 | C12: =IFERROR(VLOOKUP($A12,위치!$B:$F,4,FALSE),"") -> 35.876006 | D12: =IFERROR(VLOOKUP($A12,위치!$B:$F,5,FALSE),"") -> 128.54713 | E12: 1135 | F12: 44935 | G12: 1114 | H12: 0.9815 | K12: 27 | L12: 550 | M12: 245 | N12: 95 | O12: 57 | P12: 25 | Q12: 18 | R12: 11 | S12: 7 | T12: 7 | U12: 7 | V12: 5 | W12: 7 | X12: 10 | Y12: 7 | Z12: 10 | AA12: 6 | AB12: 2 | AC12: 2 | AD12: 3 | AE12: 1 | AF12: 1 | AG12: 1 | AH12: 1 | AI12: 1 | AN12: 1 | AP12: 2 | AW12: 1 | AX12: 1 | AY12: 1 | AZ12: 2
A13: 201289 | B13: 동성로하우스디어반오피스텔 | C13: =IFERROR(VLOOKUP($A13,위치!$B:$F,4,FALSE),"") -> 35.870571 | D13: =IFERROR(VLOOKUP($A13,위치!$B:$F,5,FALSE),"") -> 128.59324 | E13: 502 | F13: 44511 | G13: 491 | H13: 0.9781 | J13: 46 | K13: 151 | L13: 101 | M13: 58 | N13: 39 | O13: 23 | P13: 25 | Q13: 12 | R13: 5 | S13: 4 | T13: 1 | V13: 2 | X13: 1 | AC13: 1 | AD13: 1 | AE13: 2 | AF13: 1 | AG13: 2 | AJ13: 1 | AL13: 1 | AQ13: 3 | AR13: 1 | AS13: 3 | AT13: 2 | AU13: 1 | AV13: 3 | AW13: 1
A14: 201271 | B14: 대구역경남센트로팰리스 | C14: =IFERROR(VLOOKUP($A14,위치!$B:$F,4,FALSE),"") -> 35.877854 | D14: =IFERROR(VLOOKUP($A14,위치!$B:$F,5,FALSE),"") -> 128.58393 | E14: 182 | F14: 44739 | G14: 182 | H14: 1 | K14: 4 | L14: 41 | M14: 21 | N14: 24 | O14: 18 | P14: 3 | Q14: 3 | R14: 3 | T14: 6 | U14: 4 | V14: 4 | W14: 16 | X14: 12 | Y14: 7 | Z14: 2 | AA14: 7 | AB14: 1 | AC14: 3 | AD14: 2 | AM14: 1
A15: 201367 | B15: 정평역리버뷰엘(OPS) | C15: =IFERROR(VLOOKUP($A15,위치!$B:$F,4,FALSE),"") -> 35.835209 | D15: =IFERROR(VLOOKUP($A15,위치!$B:$F,5,FALSE),"") -> 128.73277 | E15: 195 | F15: 44936 | G15: 194 | H15: 0.9949 | K15: 12 | L15: 22 | M15: 15 | N15: 8 | O15: 8 | P15: 6 | Q15: 6 | R15: 2 | S15: 4 | T15: 6 | U15: 4 | V15: 10 | W15: 8 | X15: 4 | Y15: 5 | Z15: 3 | AA15: 7 | AB15: 2 | AC15: 2 | AD15: 2 | AE15: 5 | AF15: 8 | AG15: 14 | AH15: 11 | AI15: 10 | AJ15: 4 | AL15: 2 | AM15: 2 | AN15: 1 | AQ15: 1
A16: 201241 | B16: 화원 파크뷰 우방아이유쉘 | C16: =IFERROR(VLOOKUP($A16,위치!$B:$F,4,FALSE),"") -> 35.799514 | D16: =IFERROR(VLOOKUP($A16,위치!$B:$F,5,FALSE),"") -> 128.50393 | E16: 538 | F16: 44781 | G16: 529 | H16: 0.9833 | J16: 10 | K16: 230 | L16: 133 | M16: 70 | N16: 31 | O16: 15 | P16: 10 | Q16: 4 | R16: 4 | S16: 1 | T16: 1 | X16: 1 | Z16: 1 | AE16: 1 | AX16: 3 | AZ16: 1 | BA16: 1 | BB16: 10 | BD16: 2
A17: 201417 | B17: 힐스테이트앞산센트럴 | C17: =IFERROR(VLOOKUP($A17,위치!$B:$F,4,FALSE),"") -> 35.840193 | D17: =IFERROR(VLOOKUP($A17,위치!$B:$F,5,FALSE),"") -> 128.60023 | E17: 345 | F17: 45359 | G17: 316 | H17: 0.9159 | K17: 122 | L17: 108 | M17: 32 | N17: 14 | O17: 20 | P17: 3 | Q17: 2 | R17: 1 | S17: 1 | U17: 1 | V17: 1 | W17: 2 | X17: 1 | Y17: 2 | AB17: 1 | AK17: 1 | AM17: 4
A18: 201291 | B18: 장원젠트룸 | C18: =IFERROR(VLOOKUP($A18,위치!$B:$F,4,FALSE),"") -> 35.881583 | D18: =IFERROR(VLOOKUP($A18,위치!$B:$F,5,FALSE),"") -> 128.63203 | E18: 28 | F18: 44526 | G18: 28 | H18: 1 | I18: 27 | L18: 1
A19: 201244 | B19: 신암에일린의뜰 | C19: =IFERROR(VLOOKUP($A19,위치!$B:$F,4,FALSE),"") -> 35.885201 | D19: =IFERROR(VLOOKUP($A19,위치!$B:$F,5,FALSE),"") -> 128.61831 | E19: 705 | F19: 44427 | G19: 705 | H19: 1 | K19: 133 | L19: 238 | M19: 153 | N19: 78 | O19: 37 | P19: 20 | Q19: 16 | R19: 4 | S19: 6 | T19: 4 | U19: 3 | V19: 3 | W19: 1 | X19: 1 | Y19: 1 | Z19: 1 | AA19: 2 | AB19: 1 | AF19: 1 | AK19: 1 | AO19: 1
A20: 201217 | B20: 복현e편한세상 | C20: =IFERROR(VLOOKUP($A20,위치!$B:$F,4,FALSE),"") -> 35.895144 | D20: =IFERROR(VLOOKUP($A20,위치!$B:$F,5,FALSE),"") -> 128.61959 | E20: 620 | F20: 44469 | G20: 619 | H20: 0.9984 | K20: 162 | L20: 205 | M20: 103 | N20: 64 | O20: 29 | P20: 8 | Q20: 7 | R20: 5 | S20: 4 | T20: 7 | U20: 3 | V20: 5 | W20: 3 | X20: 3 | Y20: 2 | Z20: 2 | AA20: 1 | AB20: 1 | AC20: 1 | AD20: 2 | AF20: 1 | AK20: 1
A21: 201310 | B21: 대구 수성 범어 W 아파트 | C21: =IFERROR(VLOOKUP($A21,위치!$B:$F,4,FALSE),"") -> 35.858531 | D21: =IFERROR(VLOOKUP($A21,위치!$B:$F,5,FALSE),"") -> 128.62899 | E21: 1868 | F21: 45222 | G21: 1860 | H21: 0.9957 | K21: 67 | L21: 503 | M21: 383 | N21: 341 | O21: 138 | P21: 85 | Q21: 71 | R21: 76 | S21: 50 | T21: 50 | U21: 27 | V21: 16 | W21: 16 | X21: 6 | Y21: 7 | Z21: 2 | AA21: 1 | AB21: 3 | AC21: 6 | AD21: 1 | AE21: 1 | AF21: 4 | AG21: 1 | AH21: 1 | AI21: 1 | AL21: 1 | AM21: 1 | AP21: 1
A22: 201414 | B22: KEB하나스테이대구포정임대오피스텔 | C22: =IFERROR(VLOOKUP($A22,위치!$B:$F,4,FALSE),"") -> 35.871704 | D22: =IFERROR(VLOOKUP($A22,위치!$B:$F,5,FALSE),"") -> 128.59377 | E22: 287 | F22: 45261 | G22: 253 | H22: 0.8815 | J22: 41 | K22: 67 | L22: 34 | M22: 22 | N22: 13 | O22: 16 | P22: 10 | Q22: 5 | R22: 5 | S22: 4 | T22: 5 | U22: 3 | V22: 3 | W22: 3 | Z22: 2 | AA22: 2 | AB22: 1 | AC22: 3 | AF22: 1 | AG22: 1 | AH22: 1 | AI22: 3 | AJ22: 3 | AK22: 1 | AL22: 3 | AP22: 1
A23: 201335 | B23: 대구역한라하우젠트센트로 | C23: =IFERROR(VLOOKUP($A23,위치!$B:$F,4,FALSE),"") -> 35.873988 | D23: =IFERROR(VLOOKUP($A23,위치!$B:$F,5,FALSE),"") -> 128.59851 | E23: 228 | F23: 45594 | G23: 222 | H23: 0.9737 | K23: 45 | L23: 84 | M23: 43 | N23: 14 | O23: 9 | P23: 7 | Q23: 8 | R23: 4 | S23: 2 | T23: 1 | W23: 2 | X23: 2 | AE23: 1
A24: 201497 | B24: 다산월드메르디앙2차 | C24: =IFERROR(VLOOKUP($A24,위치!$B:$F,4,FALSE),"") -> 35.822434 | D24: =IFERROR(VLOOKUP($A24,위치!$B:$F,5,FALSE),"") -> 128.44371 | E24: 463 | F24: 46156 | G24: 2 | H24: 0.0043 | M24: 2
A25: 201490 | B25: 태왕디아너스 오페라 | C25: =IFERROR(VLOOKUP($A25,위치!$B:$F,4,FALSE),"") -> 35.879174 | D25: =IFERROR(VLOOKUP($A25,위치!$B:$F,5,FALSE),"") -> 128.5812 | E25: 598 | F25: 45841 | G25: 587 | H25: 0.9816 | I25: 4 | J25: 186 | K25: 185 | L25: 83 | M25: 62 | N25: 31 | O25: 16 | P25: 7 | Q25: 3 | R25: 2 | S25: 2 | T25: 3 | U25: 1 | W25: 2
A26: 201501 | B26: 해링턴플레이스트라이빗 | C26: =IFERROR(VLOOKUP($A26,위치!$B:$F,4,FALSE),"") -> 35.847355 | D26: =IFERROR(VLOOKUP($A26,위치!$B:$F,5,FALSE),"") -> 128.53245 | E26: 463 | F26: 46003 | G26: 0 | H26: 0
A27: 201492 | B27: e편한세상동대구역센텀스퀘어 | C27: =IFERROR(VLOOKUP($A27,위치!$B:$F,4,FALSE),"") -> 35.876101 | D27: =IFERROR(VLOOKUP($A27,위치!$B:$F,5,FALSE),"") -> 128.62729 | E27: 322 | F27: 45930 | G27: 228 | H27: 0.7081 | K27: 36 | L27: 54 | M27: 42 | N27: 21 | O27: 10 | P27: 25 | Q27: 6 | R27: 11 | S27: 12 | T27: 8 | U27: 3
A28: 201498 | B28: 힐스테이트동대구센트럴 | C28: =IFERROR(VLOOKUP($A28,위치!$B:$F,4,FALSE),"") -> 35.8687 | D28: =IFERROR(VLOOKUP($A28,위치!$B:$F,5,FALSE),"") -> 128.62537 | E28: 543 | F28: 46085 | G28: 456 | H28: 0.8398 | J28: 65 | K28: 116 | L28: 120 | M28: 66 | N28: 46 | O28: 43
A29: 201404 | B29: 힐스테이트 감삼센트럴 | C29: =IFERROR(VLOOKUP($A29,위치!$B:$F,4,FALSE),"") -> 35.84817 | D29: =IFERROR(VLOOKUP($A29,위치!$B:$F,5,FALSE),"") -> 128.53381 | E29: 512 | F29: 45443 | G29: 460 | H29: 0.8984 | K29: 138 | L29: 99 | M29: 59 | N29: 52 | O29: 28 | P29: 35 | Q29: 12 | R29: 14 | S29: 6 | T29: 3 | U29: 3 | V29: 3 | W29: 1 | Y29: 1 | Z29: 2 | AA29: 1 | AB29: 1 | AE29: 1 | AG29: 1
A30: 201254 | B30: 동대구역 우방아이유쉘아파트 | C30: =IFERROR(VLOOKUP($A30,위치!$B:$F,4,FALSE),"") -> 35.876609 | D30: =IFERROR(VLOOKUP($A30,위치!$B:$F,5,FALSE),"") -> 128.62475 | E30: 575 | F30: 44606 | G30: 572 | H30: 0.9948 | J30: 12 | K30: 204 | L30: 143 | M30: 96 | N30: 43 | O30: 20 | P30: 18 | Q30: 10 | R30: 4 | S30: 5 | T30: 5 | U30: 2 | V30: 1 | Z30: 1 | AD30: 2 | AS30: 1 | AX30: 1 | BB30: 2 | BC30: 2
A31: 201209 | B31: 현대 썬앤빌 중앙로역 | C31: =IFERROR(VLOOKUP($A31,위치!$B:$F,4,FALSE),"") -> 35.87143 | D31: =IFERROR(VLOOKUP($A31,위치!$B:$F,5,FALSE),"") -> 128.59919 | E31: 450 | F31: 44523 | G31: 450 | H31: 1 | J31: 116 | K31: 163 | L31: 86 | M31: 31 | N31: 19 | O31: 6 | P31: 11 | Q31: 4 | R31: 5 | S31: 3 | T31: 4 | W31: 2
A32: 201387 | B32: 경산하양파인앤유더퍼스트 | C32: =IFERROR(VLOOKUP($A32,위치!$B:$F,4,FALSE),"") -> 35.934074 | D32: =IFERROR(VLOOKUP($A32,위치!$B:$F,5,FALSE),"") -> 128.82174 | E32: 356 | F32: 44943 | G32: 356 | H32: 1 | J32: 2 | K32: 4 | L32: 1 | M32: 1 | N32: 1 | O32: 1 | P32: 2 | V32: 7 | W32: 2 | AB32: 314 | AE32: 21
A33: 201424 | B33: 동대구역센텀화성파크드림 | C33: =IFERROR(VLOOKUP($A33,위치!$B:$F,4,FALSE),"") -> 35.886183 | D33: =IFERROR(VLOOKUP($A33,위치!$B:$F,5,FALSE),"") -> 128.62819 | E33: 1458 | F33: 45370 | G33: 1456 | H33: 0.9986 | I33: 9 | J33: 623 | K33: 357 | L33: 152 | M33: 89 | N33: 63 | O33: 37 | P33: 31 | Q33: 22 | R33: 58 | S33: 7 | T33: 1 | U33: 1 | V33: 2 | W33: 1 | Y33: 1 | Z33: 1 | AJ33: 1
A34: 201332 | B34: 빌리브메트로뷰 | C34: =IFERROR(VLOOKUP($A34,위치!$B:$F,4,FALSE),"") -> 35.851433 | D34: =IFERROR(VLOOKUP($A34,위치!$B:$F,5,FALSE),"") -> 128.53962 | E34: 234 | F34: 45014 | G34: 234 | H34: 1 | K34: 14 | L34: 84 | M34: 38 | N34: 39 | O34: 18 | P34: 10 | Q34: 4 | R34: 4 | S34: 3 | T34: 3 | U34: 1 | W34: 1 | X34: 1 | AE34: 2 | AM34: 3 | AO34: 1 | AP34: 5 | AQ34: 2 | AS34: 1
A35: 201415 | B35: 경산아이파크 | C35: =IFERROR(VLOOKUP($A35,위치!$B:$F,4,FALSE),"") -> 35.843638 | D35: =IFERROR(VLOOKUP($A35,위치!$B:$F,5,FALSE),"") -> 128.76632 | E35: 977 | F35: 45377 | G35: 976 | H35: 0.999 | J35: 8 | K35: 374 | L35: 273 | M35: 100 | N35: 51 | O35: 37 | P35: 31 | Q35: 19 | R35: 67 | S35: 5 | T35: 3 | U35: 2 | V35: 1 | W35: 1 | Y35: 1 | Z35: 1 | AE35: 1 | AF35: 1
A36: 201287 | B36: 멘토르오피스텔(아이올리) | C36: =IFERROR(VLOOKUP($A36,위치!$B:$F,4,FALSE),"") -> 35.836473 | D36: =IFERROR(VLOOKUP($A36,위치!$B:$F,5,FALSE),"") -> 128.71108 | E36: 21 | F36: 44680 | G36: 21 | H36: 1 | I36: 21
A37: 201304 | B37: 시지 라온프라이빗 | C37: =IFERROR(VLOOKUP($A37,위치!$B:$F,4,FALSE),"") -> 35.834698 | D37: =IFERROR(VLOOKUP($A37,위치!$B:$F,5,FALSE),"") -> 128.71361 | E37: 207 | F37: 44845 | G37: 207 | H37: 1 | M37: 6 | N37: 11 | O37: 9 | P37: 2 | Q37: 1 | S37: 1 | T37: 1 | U37: 1 | V37: 3 | W37: 172
A38: 201380 | B38: 중산자이1단지 | C38: =IFERROR(VLOOKUP($A38,위치!$B:$F,4,FALSE),"") -> 35.832471 | D38: =IFERROR(VLOOKUP($A38,위치!$B:$F,5,FALSE),"") -> 128.72105 | E38: 1144 | F38: 45231 | G38: 1144 | H38: 1 | I38: 22 | J38: 480 | K38: 241 | L38: 194 | M38: 90 | N38: 28 | O38: 28 | P38: 22 | Q38: 12 | R38: 7 | S38: 4 | U38: 6 | V38: 2 | X38: 1 | AA38: 1 | AB38: 1 | AC38: 1 | AF38: 1 | AG38: 1 | AI38: 1 | AJ38: 1
A39: 201355 | B39: 서대구역 화성파크드림 1단지 | C39: =IFERROR(VLOOKUP($A39,위치!$B:$F,4,FALSE),"") -> 35.870553 | D39: =IFERROR(VLOOKUP($A39,위치!$B:$F,5,FALSE),"") -> 128.54721 | E39: 913 | F39: 45203 | G39: 913 | H39: 1 | I39: 20 | J39: 505 | K39: 222 | L39: 68 | M39: 33 | N39: 25 | O39: 13 | P39: 7 | Q39: 3 | R39: 1 | S39: 1 | T39: 1 | V39: 3 | W39: 1 | X39: 2 | Y39: 1 | AE39: 2 | AF39: 1 | AH39: 3 | AI39: 1
A40: 201345 | B40: 해링턴플레이스동대구 | C40: =IFERROR(VLOOKUP($A40,위치!$B:$F,4,FALSE),"") -> 35.889258 | D40: =IFERROR(VLOOKUP($A40,위치!$B:$F,5,FALSE),"") -> 128.62017 | E40: 1265 | F40: 45076 | G40: 1261 | H40: 0.9968 | K40: 8 | L40: 512 | M40: 274 | N40: 147 | O40: 121 | P40: 62 | Q40: 22 | R40: 19 | S40: 1 | T40: 2 | U40: 15 | V40: 20 | W40: 16 | X40: 17 | Y40: 5 | Z40: 2 | AA40: 4 | AB40: 1 | AC40: 1 | AD40: 1 | AF40: 2 | AG40: 1 | AH40: 4 | AI40: 1 | AJ40: 2 | AN40: 1
...

Sheet 위치
A1: 아파트명 | B1: 아파트코드 | C1: 세대수 | D1: 도로명주소 | E1: 위도 | F1: 경도
A2: 1차두성타운아파트 | B2: 22605 | C2: 285 | D2: 북구 태전로7길 10-17 | E2: 35.923942 | F2: 128.54299
A3: 2군사령부간부숙소 | B3: 201478 | C3: 43 | D3: 수성구 무열로 56 | E3: 35.863234 | F3: 128.64996
A4: 2군사령부참모관사 | B4: 201218 | C4: 10 | D4: 수성구 무열로 56 | E4: 35.863234 | F4: 128.64996
A5: 2차금류강남타운 | B5: 200004 | C5: 499 | D5: 고령군 다산면 상곡3길 28 | E5: 35.825473 | F5: 128.44794
A6: 2차대성빌라 | B6: 200301 | C6: 16 | D6: 동구 해동로 97-1 | E6: 35.890596 | F6: 128.6416
A7: 2차대자연아파트 | B7: 60703 | C7: 289 | D7: 수성구 파동로 84 | E7: 35.81165 | F7: 128.61818
A8: 3차가든하이츠 | B8: 60122 | C8: 282 | D8: 수성구 청호로 365 | E8: 35.850052 | F8: 128.63739
A9: 73신암아파트 | B9: 10150 | C9: 149 | D9: 동구 신암남로 10 | E9: 35.877268 | F9: 128.61766
A10: 78태평아파트 | B10: 4201 | C10: 122 | D10: 중구 태평로 225 | E10: 35.873855 | F10: 128.60191
A11: BC스테이션 | B11: 11221 | C11: 18 | D11: 동구 동촌로 274 | E11: 35.87956 | F11: 128.66952
A12: D.O하이넷시티 | B12: 12302 | C12: 49 | D12: 동구 안심로49길 103 | E12: 35.870505 | F12: 128.71031
A13: DH아인스 | B13: 200982 | C13: 22 | D13: 동구 효목로 47 | E13: 35.877638 | F13: 128.63969
... A2787: 힐튼빌라 | B2787: 60136 | C2787: 17 | D2787: 수성구 청호로92길 35 | E2787: 35.856433 | F2787: 128.64384
